<!-- Copyright 2021 DeepMind Technologies Limited

     Licensed under the Apache License, Version 2.0 (the "License");
     you may not use this file except in compliance with the License.
     You may obtain a copy of the License at

         http://www.apache.org/licenses/LICENSE-2.0

     Unless required by applicable law or agreed to in writing, software
     distributed under the License is distributed on an "AS IS" BASIS,
     WITHOUT WARRANTIES OR CONDITIONS OF ANY KIND, either express or implied.
     See the License for the specific language governing permissions and
     limitations under the License.
-->

<mujoco model="2-link 6-muscle arm">

    <option timestep="0.005" iterations="50" solver="Newton" tolerance="1e-10"/>

    <size njmax="50" nconmax="10" nstack="200" nuserdata="30" nuser_actuator="6"/>

    <visual>
        <rgba haze=".3 .3 .3 1"/>
	<quality shadowsize="10000" offsamples="32" numslices="64" numquads="32"/>

    </visual>

    <default>
        <joint type="hinge" pos="0 0 0" axis="0 0 1" limited="true" range="-120 120" damping="0.1"/>
        <motor ctrllimited="true" ctrlrange="-1 1" gear="30"/>
    </default>

    <asset>
        <texture type="skybox" builtin="gradient" rgb1="0.6 0.6 0.6" rgb2="0 0 0" width="512" height="512"/>

        <texture name="texplane" type="2d" builtin="checker" rgb1=".25 .25 .25" rgb2=".3 .3 .3" width="512" height="512" mark="cross" markrgb=".8 .8 .8"/>

        <material name="matplane" reflectance="0.3" texture="texplane" texrepeat="1 1" texuniform="true"/>
    </asset>

    <worldbody>
        <geom name="floor" pos="0 0 -0.5" size="0 0 1" type="plane" material="matplane"/>

        <light directional="true" diffuse=".8 .8 .8" specular=".2 .2 .2" pos="0 0 5" dir="0 0 -1"/>

        <site name="s0" pos="-0.15 0 0" size="0.02"/>
        <site name="x0" pos="0 -0.15 0" size="0.02" rgba="0 .7 0 1" group="1"/>

        <body pos="0 0 0">
            <geom name="upper arm" type="capsule" size="0.045" fromto="0 0 0  0.5 0 0" rgba=".5 .1 .1 1"/>
            <joint name="shoulder"/>
            <geom name="shoulder" type="cylinder" pos="0 0 0" size=".1 .05" rgba=".5 .1 .8 .5" mass="0" group="1"/>


            <body pos="0.5 0 0">
                <geom name="forearm" type="capsule" size="0.035" fromto="0 0 0  0.5 0 0" rgba=".5 .1 .1 1"/>
                <site name="endeffector" size="0.02" pos="0.5 0 0"/>
                <joint name="elbow"/>
		<geom name="elbow" type="cylinder" pos="0 0 0" size=".08 .05" rgba=".5 .1 .8 .5" mass="0" group="1"/>

	<body name="end_mass" pos="0.5 0 0">
		    <joint name="end_mass_x"/>
		    <joint axis="0 1 0" name="end_mass_y"/>
		    <geom conaffinity="0" contype="0" name="end_mass_geom" pos="0 0 0" rgba="0.9 0.2 0.2 1" size=".002" type="sphere" />
	</body>
        </body>
        </body>
	    <body name="target" pos="0 0 0">
    <joint armature="0" axis="1 0 0" damping="100000" frictionloss="100000" limited="true" name="target_x" pos="0
    0 0" range="-1 1" ref="0" stiffness="0" type="slide"/>
    <joint armature="0" axis="0 1 0" damping="100000" frictionloss="100000" limited="true" name="target_y" pos="0
    0 0" range="-1 1" ref="0" stiffness="0" type="slide"/>
    <geom conaffinity="0" contype="0" name="target" pos="0 0 0" rgba="0.9 0.2 0.2 1" size=".02" type="sphere"/>
            </body>

    </worldbody>


    <actuator>
        <motor name="shoulder" joint="shoulder"/>
        <motor name="elbow" joint="elbow"/>
    </actuator>
</mujoco>
